Workbook

Sheet Portada
B2: DIAGNÓSTICO FINANCIERO INTEGRAL
B3: Plantilla de Análisis Financiero Automático — CRA Consultoría
B5: DATOS DEL CLIENTE
B6: Empresa: | C6: [Nombre de la empresa]
B7: Período de análisis: | C7: [Año -2] | [Año -1] | [Año Actual]
B8: Moneda / Unidad: | C8: [MXN / Miles]
B9: Fecha de análisis: | C9: [DD/MM/AAAA]
B10: Analista: | C10: [Nombre]
B11: Revisado por: | C11: [Nombre]
B13: ÍNDICE DE HOJAS
B14: 1. Balance General | C14: Datos de entrada — Estado de Situación Financiera
B15: 2. Estado de Resultados | C15: Datos de entrada — P&L últimos 3 años
B16: 3. Análisis Horizontal | C16: Variaciones absolutas y relativas entre períodos
B17: 4. Análisis Vertical | C17: Composición porcentual de cada rubro
B18: 5. Ratios Financieros | C18: Liquidez, Solvencia, Eficiencia, Rentabilidad
B19: 6. EBITDA & CCE | C19: EBITDA, Márgenes y Ciclo de Conversión de Efectivo
B20: 7. Dashboard Ejecutivo | C20: KPIs visuales y alertas automáticas

Sheet 1. Balance General
B1: BALANCE GENERAL (ESTADO DE SITUACIÓN FINANCIERA)
B2: CONCEPTO | C2: AÑO -2 | D2: AÑO -1 | E2: AÑO ACTUAL | F2: NOTAS
B4: A C T I V O S
B5: ACTIVO TOTAL | C5: =C13+C20 -> 0 | D5: =D13+D20 -> 0 | E5: =E13+E20 -> 0
B6: ACTIVO CIRCULANTE
B7: Efectivo y equivalentes de efectivo
B8: Cuentas por cobrar a clientes (neto)
B9: Otras cuentas por cobrar
B10: Inventarios
B11: Pagos anticipados
B12: Otros activos circulantes
B13: TOTAL ACTIVO CIRCULANTE | C13: =SUM(C7:C12) -> 0 | D13: =SUM(D7:D12) -> 0 | E13: =SUM(E7:E12) -> 0
B14: ACTIVO NO CIRCULANTE
B15: Inmuebles, planta y equipo (neto)
B16: Activos intangibles y goodwill (neto)
B17: Inversiones en subsidiarias/asociadas
B18: Impuestos diferidos activo
B19: Otros activos no circulantes
B20: TOTAL ACTIVO NO CIRCULANTE | C20: =SUM(C15:C19) -> 0 | D20: =SUM(D15:D19) -> 0 | E20: =SUM(E15:E19) -> 0
B22: P A S I V O S
B23: PASIVO TOTAL | C23: =C30+C36 -> 0 | D23: =D30+D36 -> 0 | E23: =E30+E36 -> 0
B24: PASIVO CIRCULANTE
B25: Proveedores y acreedores
B26: Créditos bancarios corto plazo
B27: Porción CP de deuda largo plazo
B28: Impuestos por pagar
B29: Otros pasivos circulantes
B30: TOTAL PASIVO CIRCULANTE | C30: =SUM(C25:C29) -> 0 | D30: =SUM(D25:D29) -> 0 | E30: =SUM(E25:E29) -> 0
B31: PASIVO NO CIRCULANTE
B32: Deuda bancaria largo plazo
B33: Arrendamientos financieros LP (IFRS)
B34: Impuestos diferidos pasivo
B35: Otros pasivos no circulantes
B36: TOTAL PASIVO NO CIRCULANTE | C36: =SUM(C32:C35) -> 0 | D36: =SUM(D32:D35) -> 0 | E36: =SUM(E32:E35) -> 0
B38: C A P I T A L C O N T A B L E
B39: Capital social
B40: Prima en emisión de acciones
B41: Utilidades retenidas acumuladas
B42: Resultado del ejercicio
B43: ORI / Otros componentes de capital
...

Sheet 2. Estado de Resultados
B1: ESTADO DE RESULTADOS (PROFIT & LOSS)
B2: CONCEPTO | C2: AÑO -2 | D2: AÑO -1 | E2: AÑO ACTUAL | F2: NOTAS
B4: I N G R E S O S
B5: Ventas de productos
B6: Ventas de servicios
B7: Otros ingresos operativos
B8: INGRESOS NETOS (Ventas Netas) | C8: =SUM(C5:C7) -> 0 | D8: =SUM(D5:D7) -> 0 | E8: =SUM(E5:E7) -> 0
B9: (-) COSTO DE VENTAS / COSTO DE SERVICIOS
B10: UTILIDAD BRUTA | C10: =C8-C9 -> 0 | D10: =D8-D9 -> 0 | E10: =E8-E9 -> 0
B11: % Margen Bruto | C11: =IFERROR(C10/C8,"-") -> - | D11: =IFERROR(D10/D8,"-") -> - | E11: =IFERROR(E10/E8,"-") -> -
B13: G A S T O S D E O P E R A C I Ó N
B14: Gastos de venta
B15: Gastos de administración
B16: Otros gastos operativos
B17: TOTAL GASTOS OPERACIÓN | C17: =SUM(C14:C16) -> 0 | D17: =SUM(D14:D16) -> 0 | E17: =SUM(E14:E16) -> 0
B18: UTILIDAD DE OPERACIÓN (EBIT) | C18: =C10-C17 -> 0 | D18: =D10-D17 -> 0 | E18: =E10-E17 -> 0
B19: % Margen Operativo (EBIT) | C19: =IFERROR(C18/C8,"-") -> - | D19: =IFERROR(D18/D8,"-") -> - | E19: =IFERROR(E18/E8,"-") -> -
B21: R E S U L T A D O F I N A N C I E R O
B22: (-) Intereses devengados a cargo
B23: (+) Intereses y rendimientos ganados
B24: (±) Fluctuación cambiaria neta
B25: Otras partidas financieras netas
B26: RESULTADO INTEGRAL FINANC. (RIF) | C26: =-C22+C23+C24+C25 -> 0 | D26: =-D22+D23+D24+D25 -> 0 | E26: =-E22+E23+E24+E25 -> 0
B27: UTILIDAD ANTES DE IMPUESTOS (EBT) | C27: =C18+C26 -> 0 | D27: =D18+D26 -> 0 | E27: =E18+E26 -> 0
B28: (-) Impuesto sobre la renta (ISR/IT)
B29: (-) PTU (participación trabajadores)
B30: UTILIDAD NETA DEL EJERCICIO | C30: =C27-C28-C29 -> 0 | D30: =D27-D28-D29 -> 0 | E30: =E27-E28-E29 -> 0
B31: % Margen Neto | C31: =IFERROR(C30/C8,"-") -> - | D31: =IFERROR(D30/D8,"-") -> - | E31: =IFERROR(E30/E8,"-") -> -
B33: D A T O S C O M P L E M E N T A R I O S
B34: Depreciación del período (D&A)
B35: Amortización del período
B36: CAPEX (inversión en activos fijos)
B37: Flujo libre de efectivo operativo

Sheet 3. Análisis Horizontal
B1: ANÁLISIS HORIZONTAL — VARIACIONES ENTRE PERÍODOS
B2: CONCEPTO | C2: AÑO -2 | D2: AÑO -1 | E2: AÑO ACTUAL | F2: Var. Abs. -2→-1 | G2: Var. % -2→-1 | H2: Var. Abs. -1→0 | I2: Var. % -1→0
B4: INGRESOS NETOS | C4: ='2. Estado de Resultados'!C8 -> 0 | D4: ='2. Estado de Resultados'!D8 -> 0 | E4: ='2. Estado de Resultados'!E8 -> 0 | F4: =D4-C4 -> 0 | G4: =IFERROR((D4-C4)/ABS(C4),"-") -> - | H4: =E4-D4 -> 0 | I4: =IFERROR((E4-D4)/ABS(D4),"-") -> -
B5: Utilidad Bruta | C5: ='2. Estado de Resultados'!C10 -> 0 | D5: ='2. Estado de Resultados'!D10 -> 0 | E5: ='2. Estado de Resultados'!E10 -> 0 | F5: =D5-C5 -> 0 | G5: =IFERROR((D5-C5)/ABS(C5),"-") -> - | H5: =E5-D5 -> 0 | I5: =IFERROR((E5-D5)/ABS(D5),"-") -> -
B6: Utilidad Operativa (EBIT) | C6: ='2. Estado de Resultados'!C18 -> 0 | D6: ='2. Estado de Resultados'!D18 -> 0 | E6: ='2. Estado de Resultados'!E18 -> 0 | F6: =D6-C6 -> 0 | G6: =IFERROR((D6-C6)/ABS(C6),"-") -> - | H6: =E6-D6 -> 0 | I6: =IFERROR((E6-D6)/ABS(D6),"-") -> -
B7: Utilidad Neta | C7: ='2. Estado de Resultados'!C30 -> 0 | D7: ='2. Estado de Resultados'!D30 -> 0 | E7: ='2. Estado de Resultados'!E30 -> 0 | F7: =D7-C7 -> 0 | G7: =IFERROR((D7-C7)/ABS(C7),"-") -> - | H7: =E7-D7 -> 0 | I7: =IFERROR((E7-D7)/ABS(D7),"-") -> -
B8: ACTIVO TOTAL | C8: ='1. Balance General'!C5 -> 0 | D8: ='1. Balance General'!D5 -> 0 | E8: ='1. Balance General'!E5 -> 0 | F8: =D8-C8 -> 0 | G8: =IFERROR((D8-C8)/ABS(C8),"-") -> - | H8: =E8-D8 -> 0 | I8: =IFERROR((E8-D8)/ABS(D8),"-") -> -
B9: Activo Circulante | C9: ='1. Balance General'!C13 -> 0 | D9: ='1. Balance General'!D13 -> 0 | E9: ='1. Balance General'!E13 -> 0 | F9: =D9-C9 -> 0 | G9: =IFERROR((D9-C9)/ABS(C9),"-") -> - | H9: =E9-D9 -> 0 | I9: =IFERROR((E9-D9)/ABS(D9),"-") -> -
B10: Activo No Circulante | C10: ='1. Balance General'!C20 -> 0 | D10: ='1. Balance General'!D20 -> 0 | E10: ='1. Balance General'!E20 -> 0 | F10: =D10-C10 -> 0 | G10: =IFERROR((D10-C10)/ABS(C10),"-") -> - | H10: =E10-D10 -> 0 | I10: =IFERROR((E10-D10)/ABS(D10),"-") -> -
B11: PASIVO TOTAL | C11: ='1. Balance General'!C23 -> 0 | D11: ='1. Balance General'!D23 -> 0 | E11: ='1. Balance General'!E23 -> 0 | F11: =D11-C11 -> 0 | G11: =IFERROR((D11-C11)/ABS(C11),"-") -> - | H11: =E11-D11 -> 0 | I11: =IFERROR((E11-D11)/ABS(D11),"-") -> -
B12: Pasivo Circulante | C12: ='1. Balance General'!C30 -> 0 | D12: ='1. Balance General'!D30 -> 0 | E12: ='1. Balance General'!E30 -> 0 | F12: =D12-C12 -> 0 | G12: =IFERROR((D12-C12)/ABS(C12),"-") -> - | H12: =E12-D12 -> 0 | I12: =IFERROR((E12-D12)/ABS(D12),"-") -> -
B13: Pasivo No Circulante | C13: ='1. Balance General'!C36 -> 0 | D13: ='1. Balance General'!D36 -> 0 | E13: ='1. Balance General'!E36 -> 0 | F13: =D13-C13 -> 0 | G13: =IFERROR((D13-C13)/ABS(C13),"-") -> - | H13: =E13-D13 -> 0 | I13: =IFERROR((E13-D13)/ABS(D13),"-") -> -
B14: CAPITAL CONTABLE | C14: ='1. Balance General'!C44 -> 0 | D14: ='1. Balance General'!D44 -> 0 | E14: ='1. Balance General'!E44 -> 0 | F14: =D14-C14 -> 0 | G14: =IFERROR((D14-C14)/ABS(C14),"-") -> - | H14: =E14-D14 -> 0 | I14: =IFERROR((E14-D14)/ABS(D14),"-") -> -
B15: Efectivo | C15: ='1. Balance General'!C7 -> 0 | D15: ='1. Balance General'!D7 -> 0 | E15: ='1. Balance General'!E7 -> 0 | F15: =D15-C15 -> 0 | G15: =IFERROR((D15-C15)/ABS(C15),"-") -> - | H15: =E15-D15 -> 0 | I15: =IFERROR((E15-D15)/ABS(D15),"-") -> -
B16: Cuentas por Cobrar | C16: ='1. Balance General'!C8 -> 0 | D16: ='1. Balance General'!D8 -> 0 | E16: ='1. Balance General'!E8 -> 0 | F16: =D16-C16 -> 0 | G16: =IFERROR((D16-C16)/ABS(C16),"-") -> - | H16: =E16-D16 -> 0 | I16: =IFERROR((E16-D16)/ABS(D16),"-") -> -
B17: Inventarios | C17: ='1. Balance General'!C10 -> 0 | D17: ='1. Balance General'!D10 -> 0 | E17: ='1. Balance General'!E10 -> 0 | F17: =D17-C17 -> 0 | G17: =IFERROR((D17-C17)/ABS(C17),"-") -> - | H17: =E17-D17 -> 0 | I17: =IFERROR((E17-D17)/ABS(D17),"-") -> -
B18: Proveedores | C18: ='1. Balance General'!C25 -> 0 | D18: ='1. Balance General'!D25 -> 0 | E18: ='1. Balance General'!E25 -> 0 | F18: =D18-C18 -> 0 | G18: =IFERROR((D18-C18)/ABS(C18),"-") -> - | H18: =E18-D18 -> 0 | I18: =IFERROR((E18-D18)/ABS(D18),"-") -> -

Sheet 4. Análisis Vertical
B1: ANÁLISIS VERTICAL — COMPOSICIÓN PORCENTUAL
B2: CONCEPTO | C2: AÑO -2 | D2: AÑO -1 | E2: AÑO ACTUAL | F2: % del Total A-2 | G2: % del Total A-1 | H2: % del Total A-0 | I2: Referencia
B4: ── ANÁLISIS VERTICAL: P&L (% sobre Ingresos Netos) ──
B5: Ingresos Netos | C5: ='2. Estado de Resultados'!C8 -> 0 | D5: ='2. Estado de Resultados'!D8 -> 0 | E5: ='2. Estado de Resultados'!E8 -> 0 | F5: =IFERROR(C5/C5,"-") -> - | G5: =IFERROR(D5/D5,"-") -> - | H5: =IFERROR(E5/E5,"-") -> - | I5: % Ing.
B6: (-) Costo de Ventas | C6: ='2. Estado de Resultados'!C9 -> 0 | D6: ='2. Estado de Resultados'!D9 -> 0 | E6: ='2. Estado de Resultados'!E9 -> 0 | F6: =IFERROR(C6/C5,"-") -> - | G6: =IFERROR(D6/D5,"-") -> - | H6: =IFERROR(E6/E5,"-") -> - | I6: % Ing.
B7: Utilidad Bruta | C7: ='2. Estado de Resultados'!C10 -> 0 | D7: ='2. Estado de Resultados'!D10 -> 0 | E7: ='2. Estado de Resultados'!E10 -> 0 | F7: =IFERROR(C7/C5,"-") -> - | G7: =IFERROR(D7/D5,"-") -> - | H7: =IFERROR(E7/E5,"-") -> - | I7: % Ing.
B8: (-) Gastos Operación | C8: ='2. Estado de Resultados'!C17 -> 0 | D8: ='2. Estado de Resultados'!D17 -> 0 | E8: ='2. Estado de Resultados'!E17 -> 0 | F8: =IFERROR(C8/C5,"-") -> - | G8: =IFERROR(D8/D5,"-") -> - | H8: =IFERROR(E8/E5,"-") -> - | I8: % Ing.
B9: Utilidad Operativa EBIT | C9: ='2. Estado de Resultados'!C18 -> 0 | D9: ='2. Estado de Resultados'!D18 -> 0 | E9: ='2. Estado de Resultados'!E18 -> 0 | F9: =IFERROR(C9/C5,"-") -> - | G9: =IFERROR(D9/D5,"-") -> - | H9: =IFERROR(E9/E5,"-") -> - | I9: % Ing.
B10: Resultado Financiero RIF | C10: ='2. Estado de Resultados'!C26 -> 0 | D10: ='2. Estado de Resultados'!D26 -> 0 | E10: ='2. Estado de Resultados'!E26 -> 0 | F10: =IFERROR(C10/C5,"-") -> - | G10: =IFERROR(D10/D5,"-") -> - | H10: =IFERROR(E10/E5,"-") -> - | I10: % Ing.
B11: Utilidad Antes Imp. EBT | C11: ='2. Estado de Resultados'!C27 -> 0 | D11: ='2. Estado de Resultados'!D27 -> 0 | E11: ='2. Estado de Resultados'!E27 -> 0 | F11: =IFERROR(C11/C5,"-") -> - | G11: =IFERROR(D11/D5,"-") -> - | H11: =IFERROR(E11/E5,"-") -> - | I11: % Ing.
B12: Impuestos y PTU | C12: ='2. Estado de Resultados'!C28+'2. Estado de Resultados'!C29 -> 0 | D12: ='2. Estado de Resultados'!D28+'2. Estado de Resultados'!D29 -> 0 | E12: ='2. Estado de Resultados'!E28+'2. Estado de Resultados'!E29 -> 0 | F12: =IFERROR(C12/C5,"-") -> - | G12: =IFERROR(D12/D5,"-") -> - | H12: =IFERROR(E12/E5,"-") -> - | I12: % Ing.
B13: UTILIDAD NETA | C13: ='2. Estado de Resultados'!C30 -> 0 | D13: ='2. Estado de Resultados'!D30 -> 0 | E13: ='2. Estado de Resultados'!E30 -> 0 | F13: =IFERROR(C13/C5,"-") -> - | G13: =IFERROR(D13/D5,"-") -> - | H13: =IFERROR(E13/E5,"-") -> - | I13: % Ing.
B15: ── ANÁLISIS VERTICAL: BALANCE (% sobre Activo Total) ──
B16: Activo Circulante | C16: ='1. Balance General'!C13 -> 0 | D16: ='1. Balance General'!D13 -> 0 | E16: ='1. Balance General'!E13 -> 0 | F16: =IFERROR(C16/'1. Balance General'!C5,"-") -> - | G16: =IFERROR(D16/'1. Balance General'!D5,"-") -> - | H16: =IFERROR(E16/'1. Balance General'!E5,"-") -> - | I16: % Act.
B17: Activo No Circulante | C17: ='1. Balance General'!C20 -> 0 | D17: ='1. Balance General'!D20 -> 0 | E17: ='1. Balance General'!E20 -> 0 | F17: =IFERROR(C17/'1. Balance General'!C5,"-") -> - | G17: =IFERROR(D17/'1. Balance General'!D5,"-") -> - | H17: =IFERROR(E17/'1. Balance General'!E5,"-") -> - | I17: % Act.
B18: Pasivo Circulante | C18: ='1. Balance General'!C30 -> 0 | D18: ='1. Balance General'!D30 -> 0 | E18: ='1. Balance General'!E30 -> 0 | F18: =IFERROR(C18/'1. Balance General'!C5,"-") -> - | G18: =IFERROR(D18/'1. Balance General'!D5,"-") -> - | H18: =IFERROR(E18/'1. Balance General'!E5,"-") -> - | I18: % Act.
B19: Pasivo No Circulante | C19: ='1. Balance General'!C36 -> 0 | D19: ='1. Balance General'!D36 -> 0 | E19: ='1. Balance General'!E36 -> 0 | F19: =IFERROR(C19/'1. Balance General'!C5,"-") -> - | G19: =IFERROR(D19/'1. Balance General'!D5,"-") -> - | H19: =IFERROR(E19/'1. Balance General'!E5,"-") -> - | I19: % Act.
B20: Capital Contable | C20: ='1. Balance General'!C44 -> 0 | D20: ='1. Balance General'!D44 -> 0 | E20: ='1. Balance General'!E44 -> 0 | F20: =IFERROR(C20/'1. Balance General'!C5,"-") -> - | G20: =IFERROR(D20/'1. Balance General'!D5,"-") -> - | H20: =IFERROR(E20/'1. Balance General'!E5,"-") -> - | I20: % Act.

Sheet 5. Ratios Financieros
B1: RATIOS FINANCIEROS — ANÁLISIS INTEGRAL
B2: RATIO | C2: FÓRMULA | D2: AÑO -2 | E2: AÑO -1 | F2: AÑO ACTUAL | G2: BENCHMARK REF. | H2: INTERPRETACIÓN
B4: I. RATIOS DE LIQUIDEZ
B5: Razón Circulante | C5: Activo Circ. / Pasivo Circ. | D5: =IFERROR('1. Balance General'!C13/'1. Balance General'!C30,"-") -> - | E5: =IFERROR('1. Balance General'!D13/'1. Balance General'!D30,"-") -> - | F5: =IFERROR('1. Balance General'!E13/'1. Balance General'!E30,"-") -> - | G5: ≥ 1.5x – 2.0x | H5: Mide cobertura de pasivos CP con activos CP
B6: Prueba Ácida | C6: (Activo Circ. - Inventarios) / Pasivo Circ. | D6: =IFERROR(('1. Balance General'!C13-'1. Balance General'!C10)/'1. Balance General'!C30,"-") -> - | E6: =IFERROR(('1. Balance General'!D13-'1. Balance General'!D10)/'1. Balance General'!D30,"-") -> - | F6: =IFERROR(('1. Balance General'!E13-'1. Balance General'!E10)/'1. Balance General'!E30,"-") -> - | G6: ≥ 1.0x | H6: Excluye inventarios (menos líquidos)
B7: Razón de Efectivo | C7: Efectivo / Pasivo Circulante | D7: =IFERROR('1. Balance General'!C7/'1. Balance General'!C30,"-") -> - | E7: =IFERROR('1. Balance General'!D7/'1. Balance General'!D30,"-") -> - | F7: =IFERROR('1. Balance General'!E7/'1. Balance General'!E30,"-") -> - | G7: ≥ 0.2x | H7: Liquidez inmediata más conservadora
B8: Capital de Trabajo Neto | C8: Activo Circ. - Pasivo Circ. | D8: ='1. Balance General'!C13-'1. Balance General'!C30 -> 0 | E8: ='1. Balance General'!D13-'1. Balance General'!D30 -> 0 | F8: ='1. Balance General'!E13-'1. Balance General'!E30 -> 0 | G8: > 0 | H8: Colchón operativo disponible
B10: II. RATIOS DE SOLVENCIA / APALANCAMIENTO
B11: Deuda Total / Capital (D/E) | C11: (Pasivo CP + Pasivo LP) / Capital | D11: =IFERROR('1. Balance General'!C23/'1. Balance General'!C44,"-") -> - | E11: =IFERROR('1. Balance General'!D23/'1. Balance General'!D44,"-") -> - | F11: =IFERROR('1. Balance General'!E23/'1. Balance General'!E44,"-") -> - | G11: < 1.5x–2.0x | H11: Mayor ratio = mayor riesgo financiero
B12: Deuda Neta / EBITDA | C12: Deuda Financiera Neta / EBITDA | D12: =IFERROR(('1. Balance General'!C26+'1. Balance General'!C32-'1. Balance General'!C7)/('2. Estado de Resultados'!C18+'2. Estado de Resultados'!C34+'2. Estado de Resultados'!C35),"-") -> - | E12: =IFERROR(('1. Balance General'!D26+'1. Balance General'!D32-'1. Balance General'!D7)/('2. Estado de Resultados'!D18+'2. Estado de Resultados'!D34+'2. Estado de Resultados'!D35),"-") -> - | F12: =IFERROR(('1. Balance General'!E26+'1. Balance General'!E32-'1. Balance General'!E7)/('2. Estado de Resultados'!E18+'2. Estado de Resultados'!E34+'2. Estado de Resultados'!E35),"-") -> - | G12: < 3.0x (sector) | H12: Leverage ajustado por generación de caja
B13: Cobertura de Intereses (ICR) | C13: EBIT / Intereses a Cargo | D13: =IFERROR('2. Estado de Resultados'!C18/'2. Estado de Resultados'!C22,"-") -> - | E13: =IFERROR('2. Estado de Resultados'!D18/'2. Estado de Resultados'!D22,"-") -> - | F13: =IFERROR('2. Estado de Resultados'!E18/'2. Estado de Resultados'!E22,"-") -> - | G13: ≥ 3.0x | H13: Menor de 1.5x = riesgo de incumplimiento
B14: Razón de Endeudamiento | C14: Pasivo Total / Activo Total | D14: =IFERROR('1. Balance General'!C23/'1. Balance General'!C5,"-") -> - | E14: =IFERROR('1. Balance General'!D23/'1. Balance General'!D5,"-") -> - | F14: =IFERROR('1. Balance General'!E23/'1. Balance General'!E5,"-") -> - | G14: < 0.6x | H14: % del activo financiado con deuda
B16: III. RATIOS DE EFICIENCIA / ACTIVIDAD
B17: Rotación de Cartera (CxC) | C17: Ventas Netas / CxC Promedio | D17: =IFERROR('2. Estado de Resultados'!C8/'1. Balance General'!C8,"-") -> - | E17: =IFERROR('2. Estado de Resultados'!D8/'1. Balance General'!D8,"-") -> - | F17: =IFERROR('2. Estado de Resultados'!E8/'1. Balance General'!E8,"-") -> - | G17: Sectorial | H17: Veces por año que se cobra la cartera
B18: Días de Cuentas por Cobrar (DSO) | C18: CxC / (Ventas/365) | D18: =IFERROR('1. Balance General'!C8/('2. Estado de Resultados'!C8/365),"-") -> - | E18: =IFERROR('1. Balance General'!D8/('2. Estado de Resultados'!D8/365),"-") -> - | F18: =IFERROR('1. Balance General'!E8/('2. Estado de Resultados'!E8/365),"-") -> - | G18: 30 – 60 días | H18: Tiempo promedio de cobro a clientes
B19: Días de Inventario (DIO) | C19: Inventario / (Costo Vtas/365) | D19: =IFERROR('1. Balance General'!C10/('2. Estado de Resultados'!C9/365),"-") -> - | E19: =IFERROR('1. Balance General'!D10/('2. Estado de Resultados'!D9/365),"-") -> - | F19: =IFERROR('1. Balance General'!E10/('2. Estado de Resultados'!E9/365),"-") -> - | G19: Sectorial | H19: Días promedio de rotación de inventario
B20: Días de Cuentas por Pagar (DPO) | C20: Proveedores / (Costo Vtas/365) | D20: =IFERROR('1. Balance General'!C25/('2. Estado de Resultados'!C9/365),"-") -> - | E20: =IFERROR('1. Balance General'!D25/('2. Estado de Resultados'!D9/365),"-") -> - | F20: =IFERROR('1. Balance General'!E25/('2. Estado de Resultados'!E9/365),"-") -> - | G20: 30 – 60 días | H20: Días de crédito recibido de proveedores
B21: Rotación de Activos Totales | C21: Ventas Netas / Activo Total | D21: =IFERROR('2. Estado de Resultados'!C8/'1. Balance General'!C5,"-") -> - | E21: =IFERROR('2. Estado de Resultados'!D8/'1. Balance General'!D5,"-") -> - | F21: =IFERROR('2. Estado de Resultados'!E8/'1. Balance General'!E5,"-") -> - | G21: ≥ 1.0x | H21: Eficiencia en uso de activos para generar ventas
B23: IV. RATIOS DE RENTABILIDAD
B24: Margen Bruto | C24: Utilidad Bruta / Ventas Netas | D24: =IFERROR('2. Estado de Resultados'!C10/'2. Estado de Resultados'!C8,"-") -> - | E24: =IFERROR('2. Estado de Resultados'!D10/'2. Estado de Resultados'!D8,"-") -> - | F24: =IFERROR('2. Estado de Resultados'!E10/'2. Estado de Resultados'!E8,"-") -> - | G24: Sectorial | H24: % de ventas remanente tras costos directos
B25: Margen EBIT (Operativo) | C25: EBIT / Ventas Netas | D25: =IFERROR('2. Estado de Resultados'!C18/'2. Estado de Resultados'!C8,"-") -> - | E25: =IFERROR('2. Estado de Resultados'!D18/'2. Estado de Resultados'!D8,"-") -> - | F25: =IFERROR('2. Estado de Resultados'!E18/'2. Estado de Resultados'!E8,"-") -> - | G25: Sectorial | H25: Rentabilidad operativa antes de financieros
B26: Margen Neto | C26: Utilidad Neta / Ventas Netas | D26: =IFERROR('2. Estado de Resultados'!C30/'2. Estado de Resultados'!C8,"-") -> - | E26: =IFERROR('2. Estado de Resultados'!D30/'2. Estado de Resultados'!D8,"-") -> - | F26: =IFERROR('2. Estado de Resultados'!E30/'2. Estado de Resultados'!E8,"-") -> - | G26: Sectorial | H26: Rentabilidad final después de impuestos
B27: ROA (Return on Assets) | C27: Utilidad Neta / Activo Total | D27: =IFERROR('2. Estado de Resultados'!C30/'1. Balance General'!C5,"-") -> - | E27: =IFERROR('2. Estado de Resultados'!D30/'1. Balance General'!D5,"-") -> - | F27: =IFERROR('2. Estado de Resultados'!E30/'1. Balance General'!E5,"-") -> - | G27: ≥ 5% | H27: Rentabilidad sobre la base de activos totales
B28: ROE (Return on Equity) | C28: Utilidad Neta / Capital Contable | D28: =IFERROR('2. Estado de Resultados'!C30/'1. Balance General'!C44,"-") -> - | E28: =IFERROR('2. Estado de Resultados'!D30/'1. Balance General'!D44,"-") -> - | F28: =IFERROR('2. Estado de Resultados'!E30/'1. Balance General'!E44,"-") -> - | G28: ≥ 10% | H28: Retorno para los accionistas sobre capital invertido
B29: ROCE (Return on Capital Employed) | C29: EBIT / (Activo Total - Pasivo Circ.) | D29: =IFERROR('2. Estado de Resultados'!C18/('1. Balance General'!C5-'1. Balance General'!C30),"-") -> - | E29: =IFERROR('2. Estado de Resultados'!D18/('1. Balance General'!D5-'1. Balance General'!D30),"-") -> - | F29: =IFERROR('2. Estado de Resultados'!E18/('1. Balance General'!E5-'1. Balance General'!E30),"-") -> - | G29: ≥ 15% | H29: Eficiencia del capital empleado en operaciones

Sheet 6. EBITDA & CCE
B1: EBITDA, MÁRGENES Y CICLO DE CONVERSIÓN DE EFECTIVO
B2: CONCEPTO | C2: AÑO -2 | D2: AÑO -1 | E2: AÑO ACTUAL | F2: COMENTARIO
B4: I. CÁLCULO DEL EBITDA
B5: Utilidad Neta | C5: ='2. Estado de Resultados'!C30 -> 0 | D5: ='2. Estado de Resultados'!D30 -> 0
B6: (+) Impuestos (ISR + PTU) | C6: ='2. Estado de Resultados'!C28+'2. Estado de Resultados'!C29 -> 0 | D6: ='2. Estado de Resultados'!D28+'2. Estado de Resultados'!D29 -> 0
B7: (+) Gastos Financieros Netos | C7: ='2. Estado de Resultados'!C22-'2. Estado de Resultados'!C23 -> 0 | D7: ='2. Estado de Resultados'!D22-'2. Estado de Resultados'!D23 -> 0
B8: (+) Depreciación y Amortización | C8: ='2. Estado de Resultados'!C34+'2. Estado de Resultados'!C35 -> 0 | D8: ='2. Estado de Resultados'!D34+'2. Estado de Resultados'!D35 -> 0
B9: EBITDA | C9: =C5+C6+C7+C8 -> 0 | D9: =D5+D6+D7+D8 -> 0 | E9: ='2. Estado de Resultados'!E30+'2. Estado de Resultados'!E28+'2. Estado de Resultados'!E29+'2. Estado de Resultados'!E22-'2. Estado de Resultados'!E23+'2. Estado de Resultados'!E34+'2. Estado de Resultados'!E35 -> 0
B10: Margen EBITDA (%) | C10: =IFERROR(C9/'2. Estado de Resultados'!C8,"-") -> - | D10: =IFERROR(D9/'2. Estado de Resultados'!D8,"-") -> - | E10: =IFERROR(E9/'2. Estado de Resultados'!E8,"-") -> -
B11: EBITDA - CAPEX (FCF Proxy) | C11: =IFERROR(C9-'2. Estado de Resultados'!C36,"-") -> 0 | D11: =IFERROR(D9-'2. Estado de Resultados'!D36,"-") -> 0 | E11: =IFERROR(E9-'2. Estado de Resultados'!E36,"-") -> 0
B13: II. CICLO DE CONVERSIÓN DE EFECTIVO
B14: Días de Cuentas por Cobrar (DSO) | C14: =IFERROR('1. Balance General'!C8/('2. Estado de Resultados'!C8/365),0) -> 0 | D14: =IFERROR('1. Balance General'!D8/('2. Estado de Resultados'!D8/365),0) -> 0 | E14: =IFERROR('1. Balance General'!E8/('2. Estado de Resultados'!E8/365),0) -> 0
B15: Días de Inventario (DIO) | C15: =IFERROR('1. Balance General'!C10/('2. Estado de Resultados'!C9/365),0) -> 0 | D15: =IFERROR('1. Balance General'!D10/('2. Estado de Resultados'!D9/365),0) -> 0 | E15: =IFERROR('1. Balance General'!E10/('2. Estado de Resultados'!E9/365),0) -> 0
B16: Días de Cuentas por Pagar (DPO) | C16: =IFERROR('1. Balance General'!C25/('2. Estado de Resultados'!C9/365),0) -> 0 | D16: =IFERROR('1. Balance General'!D25/('2. Estado de Resultados'!D9/365),0) -> 0 | E16: =IFERROR('1. Balance General'!E25/('2. Estado de Resultados'!E9/365),0) -> 0
B17: CICLO DE CONVERSIÓN (CCE = DSO + DIO - DPO) | C17: =C14+C15-C16 -> 0 | D17: =D14+D15-D16 -> 0 | E17: =E14+E15-E16 -> 0
B19: III. ANÁLISIS DE FLUJO DE CAJA LIBRE (FCF)
B20: EBITDA | C20: =C9 -> 0 | D20: =D9 -> 0 | E20: =E9 -> 0
B21: (-) CAPEX | C21: ='2. Estado de Resultados'!C36 -> 0 | D21: ='2. Estado de Resultados'!D36 -> 0 | E21: ='2. Estado de Resultados'!E36 -> 0
B22: (-) Variación en Capital de Trabajo | C22: =('1. Balance General'!C13-'1. Balance General'!C30)-('1. Balance General'!D13-'1. Balance General'!D30) -> 0 | D22: =('1. Balance General'!D13-'1. Balance General'!D30)-('1. Balance General'!E13-'1. Balance General'!E30) -> 0 | E22: =('1. Balance General'!D13-'1. Balance General'!D30)-('1. Balance General'!E13-'1. Balance General'!E30) -> 0
B23: (-) Impuestos Pagados (Proxy) | C23: =-('2. Estado de Resultados'!C28+'2. Estado de Resultados'!C29) -> 0 | D23: =-('2. Estado de Resultados'!D28+'2. Estado de Resultados'!D29) -> 0 | E23: =-('2. Estado de Resultados'!E28+'2. Estado de Resultados'!E29) -> 0
B24: FLUJO DE CAJA LIBRE ESTIMADO (FCF) | C24: =C20-C21-C22-C23 -> 0 | D24: =D20-D21-D22-D23 -> 0 | E24: =E20-E21-E22-E23 -> 0

Sheet 7. Dashboard Ejecutivo
B1: DASHBOARD EJECUTIVO — DIAGNÓSTICO FINANCIERO
B2: Todos los valores se actualizan automáticamente al ingresar datos en las hojas de Balance y Estado de Resultados
B4: INGRESOS NETOS | C4: EBITDA | D4: MARGEN EBITDA | E4: UTILIDAD NETA | F4: MARGEN NETO
B5: ='2. Estado de Resultados'!E8 -> 0 | C5: ='6. EBITDA & CCE'!E9 -> 0 | D5: ='6. EBITDA & CCE'!E10 -> - | E5: ='2. Estado de Resultados'!E30 -> 0 | F5: =IFERROR('2. Estado de Resultados'!E30/'2. Estado de Resultados'!E8,"-") -> -
B6: Año Actual | C6: Año Actual | D6: Año Actual | E6: Año Actual | F6: Año Actual
B9: DEUDA NETA / EBITDA | C9: RAZÓN CIRCULANTE | D9: ROE | E9: CCE (DÍAS) | F9: COBERTURA INT. (ICR)
B10: =IFERROR(('1. Balance General'!E26+'1. Balance General'!E32-'1. Balance General'!E7)/('6. EBITDA & CCE'!E9),"-") -> - | C10: =IFERROR('1. Balance General'!E13/'1. Balance General'!E30,"-") -> - | D10: =IFERROR('2. Estado de Resultados'!E30/'1. Balance General'!E44,"-") -> - | E10: ='6. EBITDA & CCE'!E17 -> 0 | F10: =IFERROR('2. Estado de Resultados'!E18/'2. Estado de Resultados'!E22,"-") -> -
B11: Leverage | C11: Liquidez | D11: Rentabilidad | E11: Ciclo Efectivo | F11: Solvencia
B15: RESUMEN DE TENDENCIAS — MÉTRICAS CLAVE
B16: MÉTRICA | C16: AÑO -2 | D16: AÑO -1 | E16: AÑO ACTUAL | F16: TENDENCIA | G16: SEMÁFORO
B17: Ingresos Netos | C17: ='2. Estado de Resultados'!C8 -> 0 | D17: ='2. Estado de Resultados'!D8 -> 0 | E17: ='2. Estado de Resultados'!E8 -> 0 | F17: =IF(ISNUMBER(E17),IF(E17>D17,"▲ MEJORA","▼ BAJA"),"-") -> ▼ BAJA | G17: =IF(ISNUMBER(E17),IF(E17>C17,"● VERDE","● ATENCIÓN"),"-") -> ● ATENCIÓN
B18: Utilidad Bruta | C18: ='2. Estado de Resultados'!C10 -> 0 | D18: ='2. Estado de Resultados'!D10 -> 0 | E18: ='2. Estado de Resultados'!E10 -> 0 | F18: =IF(ISNUMBER(E18),IF(E18>D18,"▲ MEJORA","▼ BAJA"),"-") -> ▼ BAJA | G18: =IF(ISNUMBER(E18),IF(E18>C18,"● VERDE","● ATENCIÓN"),"-") -> ● ATENCIÓN
B19: EBIT | C19: ='2. Estado de Resultados'!C18 -> 0 | D19: ='2. Estado de Resultados'!D18 -> 0 | E19: ='2. Estado de Resultados'!E18 -> 0 | F19: =IF(ISNUMBER(E19),IF(E19>D19,"▲ MEJORA","▼ BAJA"),"-") -> ▼ BAJA | G19: =IF(ISNUMBER(E19),IF(E19>C19,"● VERDE","● ATENCIÓN"),"-") -> ● ATENCIÓN
B20: EBITDA | C20: ='6. EBITDA & CCE'!C9 -> 0 | D20: ='6. EBITDA & CCE'!D9 -> 0 | E20: ='6. EBITDA & CCE'!E9 -> 0 | F20: =IF(ISNUMBER(E20),IF(E20>D20,"▲ MEJORA","▼ BAJA"),"-") -> ▼ BAJA | G20: =IF(ISNUMBER(E20),IF(E20>C20,"● VERDE","● ATENCIÓN"),"-") -> ● ATENCIÓN
B21: Utilidad Neta | C21: ='2. Estado de Resultados'!C30 -> 0 | D21: ='2. Estado de Resultados'!D30 -> 0 | E21: ='2. Estado de Resultados'!E30 -> 0 | F21: =IF(ISNUMBER(E21),IF(E21>D21,"▲ MEJORA","▼ BAJA"),"-") -> ▼ BAJA | G21: =IF(ISNUMBER(E21),IF(E21>C21,"● VERDE","● ATENCIÓN"),"-") -> ● ATENCIÓN
B22: Margen Bruto % | C22: ='2. Estado de Resultados'!C11 -> - | D22: ='2. Estado de Resultados'!D11 -> - | E22: ='2. Estado de Resultados'!E11 -> - | F22: =IF(ISNUMBER(E22),IF(E22>D22,"▲ MEJORA","▼ BAJA"),"-") -> - | G22: =IF(ISNUMBER(E22),IF(E22>C22,"● VERDE","● ATENCIÓN"),"-") -> -
B23: Margen EBIT % | C23: ='2. Estado de Resultados'!C19 -> - | D23: ='2. Estado de Resultados'!D19 -> - | E23: ='2. Estado de Resultados'!E19 -> - | F23: =IF(ISNUMBER(E23),IF(E23>D23,"▲ MEJORA","▼ BAJA"),"-") -> - | G23: =IF(ISNUMBER(E23),IF(E23>C23,"● VERDE","● ATENCIÓN"),"-") -> -
B24: Margen Neto % | C24: ='2. Estado de Resultados'!C31 -> - | D24: ='2. Estado de Resultados'!D31 -> - | E24: ='2. Estado de Resultados'!E31 -> - | F24: =IF(ISNUMBER(E24),IF(E24>D24,"▲ MEJORA","▼ BAJA"),"-") -> - | G24: =IF(ISNUMBER(E24),IF(E24>C24,"● VERDE","● ATENCIÓN"),"-") -> -
B25: CCE (días) | C25: ='6. EBITDA & CCE'!C17 -> 0 | D25: ='6. EBITDA & CCE'!D17 -> 0 | E25: ='6. EBITDA & CCE'!E17 -> 0 | F25: =IF(ISNUMBER(E25),IF(E25>D25,"▲ MEJORA","▼ BAJA"),"-") -> ▼ BAJA | G25: =IF(ISNUMBER(E25),IF(E25>C25,"● VERDE","● ATENCIÓN"),"-") -> ● ATENCIÓN
B26: Razón Circulante | C26: =IFERROR('1. Balance General'!C13/'1. Balance General'!C30,"-") -> - | D26: =IFERROR('1. Balance General'!D13/'1. Balance General'!D30,"-") -> - | E26: =IFERROR('1. Balance General'!E13/'1. Balance General'!E30,"-") -> - | F26: =IF(ISNUMBER(E26),IF(E26>D26,"▲ MEJORA","▼ BAJA"),"-") -> - | G26: =IF(ISNUMBER(E26),IF(E26>C26,"● VERDE","● ATENCIÓN"),"-") -> -

Sheet ⚠ Caveats
A1: CAVEATS — LIMITACIONES DEL DIAGNÓSTICO FINANCIERO
B2: 1. NATURALEZA DEL ANÁLISIS
B3: El presente diagnóstico se basa exclusivamente en la información financiera proporcionada por el cliente. No constituye una auditoría de estados financieros conforme a ninguna norma de auditoría generalmente aceptada (NAGAS, ISA, SAS). No se ha verificado la integridad ni exactitud de los datos fuente.
B4: 2. LIMITACIONES DE RESPONSABILIDAD
B5: CRA Consultoría y los analistas responsables del presente diagnóstico no asumen responsabilidad alguna por decisiones de negocio, financieras o legales tomadas con base en este análisis, si la información suministrada por el cliente resulta inexacta, incompleta o fraudulenta.
B6: 3. BENCHMARKING SECTORIAL
B7: Los rangos de referencia (benchmarks) utilizados para evaluar ratios provienen de fuentes públicas y bases de datos sectoriales disponibles a la fecha del análisis. Pueden diferir materialmente del desempeño real de la industria específica del cliente, su geografía o su escala de operaciones.
B8: 4. PROYECCIONES Y ANÁLISIS DE SENSIBILIDAD
B9: Cualquier proyección o análisis de sensibilidad incluido en este diagnóstico se basa en supuestos razonables a la fecha de elaboración. Los resultados futuros reales pueden diferir materialmente de las proyecciones como consecuencia de eventos imprevistos, cambios regulatorios o macroeconómicos.
B10: 5. CONFIDENCIALIDAD
B11: Este documento es de carácter estrictamente confidencial. Su reproducción, distribución o divulgación a terceros sin autorización expresa de CRA Consultoría está prohibida.
